2024-04-14T23:36:34 {"cpu": 0.87890625, "cpu_total": 4, "cpu_usage": 0.2197265625, "memory": 5135.0, "memory_total": 8874.0, "memory_usage": 0.5786567500563444, "pipeline_run_id": 124, "pipeline_schedule_id": 1, "pipeline_uuid": "fantastic_spellcaster", "hostname": "65ebb88fe12a", "level": "INFO", "message": "Pipeline fantastic_spellcaster for run 124 in schedule 1 is alive.", "timestamp": 1713137794.61293, "uuid": "b284d57a407f4d85b24e855155ffa9a7"}
2024-04-14T23:36:53 {"cpu": 0.9736328125, "cpu_total": 4, "cpu_usage": 0.243408203125, "memory": 5387.0, "memory_total": 8874.0, "memory_usage": 0.6070543159792653, "pipeline_run_id": 124, "pipeline_schedule_id": 1, "pipeline_uuid": "fantastic_spellcaster", "hostname": "65ebb88fe12a", "level": "INFO", "message": "Pipeline fantastic_spellcaster for run 124 in schedule 1 is alive.", "timestamp": 1713137813.286577, "uuid": "8a01833d529a4a5ebd9101ffd6e2ef79"}
2024-04-14T23:37:06 {"cpu": 0.99072265625, "cpu_total": 4, "cpu_usage": 0.2476806640625, "memory": 5420.0, "memory_total": 8874.0, "memory_usage": 0.610773044850124, "pipeline_run_id": 124, "pipeline_schedule_id": 1, "pipeline_uuid": "fantastic_spellcaster", "hostname": "65ebb88fe12a", "level": "INFO", "message": "Pipeline fantastic_spellcaster for run 124 in schedule 1 is alive.", "timestamp": 1713137826.818687, "uuid": "ebce79f2766f4a1d8c443c55bc48c407"}
2024-04-14T23:37:18 {"cpu": 1.017578125, "cpu_total": 4, "cpu_usage": 0.25439453125, "memory": 5535.0, "memory_total": 8874.0, "memory_usage": 0.6237322515212982, "pipeline_run_id": 124, "pipeline_schedule_id": 1, "pipeline_uuid": "fantastic_spellcaster", "hostname": "65ebb88fe12a", "level": "INFO", "message": "Pipeline fantastic_spellcaster for run 124 in schedule 1 is alive.", "timestamp": 1713137838.700886, "uuid": "d8b8405df82b48ef88bc5dfc3e3a11c7"}
2024-04-14T23:37:30 {"cpu": 1.0498046875, "cpu_total": 4, "cpu_usage": 0.262451171875, "memory": 5444.0, "memory_total": 8874.0, "memory_usage": 0.6134775749380211, "pipeline_run_id": 124, "pipeline_schedule_id": 1, "pipeline_uuid": "fantastic_spellcaster", "hostname": "65ebb88fe12a", "level": "INFO", "message": "Pipeline fantastic_spellcaster for run 124 in schedule 1 is alive.", "timestamp": 1713137850.15369, "uuid": "98d5288a968348dfaeacb476b6eb0b62"}
2024-04-14T23:37:41 {"cpu": 1.08740234375, "cpu_total": 4, "cpu_usage": 0.2718505859375, "memory": 5106.0, "memory_total": 8874.0, "memory_usage": 0.5753887762001352, "pipeline_run_id": 124, "pipeline_schedule_id": 1, "pipeline_uuid": "fantastic_spellcaster", "hostname": "65ebb88fe12a", "level": "INFO", "message": "Pipeline fantastic_spellcaster for run 124 in schedule 1 is alive.", "timestamp": 1713137861.421758, "uuid": "7deba8bb08574df99c31ba812508a450"}
2024-04-14T23:37:49 {"cpu": 1.09765625, "cpu_total": 4, "cpu_usage": 0.2744140625, "memory": 5207.0, "memory_total": 8874.0, "memory_usage": 0.586770340320036, "pipeline_run_id": 124, "pipeline_schedule_id": 1, "pipeline_uuid": "fantastic_spellcaster", "hostname": "65ebb88fe12a", "level": "INFO", "message": "Pipeline fantastic_spellcaster for run 124 in schedule 1 is alive.", "timestamp": 1713137869.661438, "uuid": "c535cf15b84749c0bd1cf30d2ad67e42"}
2024-04-14T23:37:58 {"cpu": 1.1123046875, "cpu_total": 4, "cpu_usage": 0.278076171875, "memory": 5524.0, "memory_total": 8874.0, "memory_usage": 0.6224926752310119, "pipeline_run_id": 124, "pipeline_schedule_id": 1, "pipeline_uuid": "fantastic_spellcaster", "hostname": "65ebb88fe12a", "level": "INFO", "message": "Pipeline fantastic_spellcaster for run 124 in schedule 1 is alive.", "timestamp": 1713137878.095753, "uuid": "b87b99707e3a49f193aef410643efe13"}
2024-04-14T23:38:06 {"cpu": 1.10595703125, "cpu_total": 4, "cpu_usage": 0.2764892578125, "memory": 5420.0, "memory_total": 8874.0, "memory_usage": 0.610773044850124, "pipeline_run_id": 124, "pipeline_schedule_id": 1, "pipeline_uuid": "fantastic_spellcaster", "hostname": "65ebb88fe12a", "level": "INFO", "message": "Pipeline fantastic_spellcaster for run 124 in schedule 1 is alive.", "timestamp": 1713137886.324319, "uuid": "63469c56d2ec49c9aae5fe75c755fcd3"}
2024-04-14T23:38:15 {"block_run_id": 248, "block_uuid": "dwn_ticker_price", "pipeline_run_id": 124, "pipeline_schedule_id": 1, "pipeline_uuid": "fantastic_spellcaster", "hostname": "65ebb88fe12a", "level": "INFO", "message": "Execute PipelineRun 124, BlockRun 248: pipeline fantastic_spellcaster block dwn_ticker_price", "timestamp": 1713137895.590934, "uuid": "575af0ae2a924511a86cc969664d8626"}
2024-04-14T23:38:16 {"cpu": 1.130859375, "cpu_total": 4, "cpu_usage": 0.28271484375, "memory": 5147.0, "memory_total": 8874.0, "memory_usage": 0.580009015100293, "pipeline_run_id": 124, "pipeline_schedule_id": 1, "pipeline_uuid": "fantastic_spellcaster", "hostname": "65ebb88fe12a", "level": "INFO", "message": "Pipeline fantastic_spellcaster for run 124 in schedule 1 is alive.", "timestamp": 1713137896.97658, "uuid": "269e9278a30c448fae8bff7a2dd6e4f2"}
2024-04-14T23:38:18 {"block_run_id": 248, "block_uuid": "dwn_ticker_price", "pipeline_run_id": 124, "pipeline_schedule_id": 1, "pipeline_uuid": "fantastic_spellcaster", "hostname": "65ebb88fe12a", "level": "EXCEPTION", "message": "BlockRun 248 (block_uuid: dwn_ticker_price) failed.", "timestamp": 1713137898.145884, "uuid": "9aafa7c8f76145b081462f8f4b267673", "error": ["Traceback (most recent call last):\n  File \"/usr/local/lib/python3.10/site-packages/pandas/core/indexes/base.py\", line 3802, in get_loc\n    return self._engine.get_loc(casted_key)\n  File \"pandas/_libs/index.pyx\", line 138, in pandas._libs.index.IndexEngine.get_loc\n  File \"pandas/_libs/index.pyx\", line 165, in pandas._libs.index.IndexEngine.get_loc\n  File \"pandas/_libs/hashtable_class_helper.pxi\", line 5745, in pandas._libs.hashtable.PyObjectHashTable.get_item\n  File \"pandas/_libs/hashtable_class_helper.pxi\", line 5753, in pandas._libs.hashtable.PyObjectHashTable.get_item\nKeyError: 'Open'\n\nThe above exception was the direct cause of the following exception:\n\nTraceback (most recent call last):\n  File \"/usr/local/lib/python3.10/site-packages/mage_ai/data_preparation/executors/block_executor.py\", line 605, in execute\n    result = __execute_with_retry()\n  File \"/usr/local/lib/python3.10/site-packages/mage_ai/shared/retry.py\", line 54, in retry_func\n    raise e\n  File \"/usr/local/lib/python3.10/site-packages/mage_ai/shared/retry.py\", line 38, in retry_func\n    return func(*args, **kwargs)\n  File \"/usr/local/lib/python3.10/site-packages/mage_ai/data_preparation/executors/block_executor.py\", line 578, in __execute_with_retry\n    return self._execute(\n  File \"/usr/local/lib/python3.10/site-packages/mage_ai/data_preparation/executors/block_executor.py\", line 1052, in _execute\n    result = self.block.execute_sync(\n  File \"/usr/local/lib/python3.10/site-packages/mage_ai/data_preparation/models/block/__init__.py\", line 1285, in execute_sync\n    raise err\n  File \"/usr/local/lib/python3.10/site-packages/mage_ai/data_preparation/models/block/__init__.py\", line 1194, in execute_sync\n    output = self.execute_block(\n  File \"/usr/local/lib/python3.10/site-packages/mage_ai/data_preparation/models/block/__init__.py\", line 1509, in execute_block\n    outputs = self._execute_block(\n  File \"/usr/local/lib/python3.10/site-packages/mage_ai/data_preparation/models/block/__init__.py\", line 1665, in _execute_block\n    outputs = self.execute_block_function(\n  File \"/usr/local/lib/python3.10/site-packages/mage_ai/data_preparation/models/block/__init__.py\", line 1704, in execute_block_function\n    output = block_function_updated(*input_vars, **global_vars)\n  File \"<string>\", line 32, in load_data\n  File \"/home/src/./src/data_ingestion/download_ticker_data.py\", line 64, in download_ticker_data\n    response_dict[symbol] = vbt.AlpacaData.download_symbol(symbol, start=start_date, end=end_date)\n  File \"/usr/local/lib/python3.10/site-packages/vectorbt/data/custom.py\", line 917, in download_symbol\n    df['Open'] = df['Open'].astype(float)\n  File \"/usr/local/lib/python3.10/site-packages/pandas/core/frame.py\", line 3807, in __getitem__\n    indexer = self.columns.get_loc(key)\n  File \"/usr/local/lib/python3.10/site-packages/pandas/core/indexes/base.py\", line 3804, in get_loc\n    raise KeyError(key) from err\nKeyError: 'Open'\n"], "error_stack": [["  File \"/usr/local/bin/mage\", line 8, in <module>\n    sys.exit(app())\n", "  File \"/usr/local/lib/python3.10/site-packages/typer/main.py\", line 311, in __call__\n    return get_command(self)(*args, **kwargs)\n", "  File \"/usr/local/lib/python3.10/site-packages/click/core.py\", line 1130, in __call__\n    return self.main(*args, **kwargs)\n", "  File \"/usr/local/lib/python3.10/site-packages/typer/core.py\", line 778, in main\n    return _main(\n", "  File \"/usr/local/lib/python3.10/site-packages/typer/core.py\", line 216, in _main\n    rv = self.invoke(ctx)\n", "  File \"/usr/local/lib/python3.10/site-packages/click/core.py\", line 1657, in invoke\n    return _process_result(sub_ctx.command.invoke(sub_ctx))\n", "  File \"/usr/local/lib/python3.10/site-packages/click/core.py\", line 1404, in invoke\n    return ctx.invoke(self.callback, **ctx.params)\n", "  File \"/usr/local/lib/python3.10/site-packages/click/core.py\", line 760, in invoke\n    return __callback(*args, **kwargs)\n", "  File \"/usr/local/lib/python3.10/site-packages/typer/main.py\", line 683, in wrapper\n    return callback(**use_params)  # type: ignore\n", "  File \"/usr/local/lib/python3.10/site-packages/mage_ai/cli/main.py\", line 163, in start\n    start_server(\n", "  File \"/usr/local/lib/python3.10/site-packages/mage_ai/server/server.py\", line 659, in start_server\n    scheduler_manager.start_scheduler()\n", "  File \"/usr/local/lib/python3.10/site-packages/mage_ai/server/scheduler_manager.py\", line 87, in start_scheduler\n    proc.start()\n", "  File \"/usr/local/lib/python3.10/multiprocessing/process.py\", line 121, in start\n    self._popen = self._Popen(self)\n", "  File \"/usr/local/lib/python3.10/multiprocessing/context.py\", line 224, in _Popen\n    return _default_context.get_context().Process._Popen(process_obj)\n", "  File \"/usr/local/lib/python3.10/multiprocessing/context.py\", line 281, in _Popen\n    return Popen(process_obj)\n", "  File \"/usr/local/lib/python3.10/multiprocessing/popen_fork.py\", line 19, in __init__\n    self._launch(process_obj)\n", "  File \"/usr/local/lib/python3.10/multiprocessing/popen_fork.py\", line 71, in _launch\n    code = process_obj._bootstrap(parent_sentinel=child_r)\n", "  File \"/usr/local/lib/python3.10/multiprocessing/process.py\", line 314, in _bootstrap\n    self.run()\n", "  File \"/usr/local/lib/python3.10/multiprocessing/process.py\", line 108, in run\n    self._target(*self._args, **self._kwargs)\n", "  File \"/usr/local/lib/python3.10/site-packages/mage_ai/orchestration/db/process.py\", line 15, in start_session_and_run\n    results = target(*args)\n", "  File \"/usr/local/lib/python3.10/site-packages/mage_ai/server/scheduler_manager.py\", line 50, in run_scheduler\n    LoopTimeTrigger().start()\n", "  File \"/usr/local/lib/python3.10/site-packages/mage_ai/orchestration/triggers/loop_time_trigger.py\", line 14, in start\n    self.run()\n", "  File \"/usr/local/lib/python3.10/site-packages/mage_ai/orchestration/triggers/time_trigger.py\", line 11, in run\n    schedule_all()\n", "  File \"/usr/local/lib/python3.10/site-packages/mage_ai/orchestration/pipeline_scheduler_original.py\", line 1552, in schedule_all\n    PipelineScheduler(r).start()\n", "  File \"/usr/local/lib/python3.10/site-packages/mage_ai/orchestration/db/__init__.py\", line 149, in func_with_rollback\n    return func(*args, **kwargs)\n", "  File \"/usr/local/lib/python3.10/site-packages/mage_ai/orchestration/pipeline_scheduler_original.py\", line 182, in start\n    self.schedule()\n", "  File \"/usr/local/lib/python3.10/site-packages/mage_ai/orchestration/db/__init__.py\", line 149, in func_with_rollback\n    return func(*args, **kwargs)\n", "  File \"/usr/local/lib/python3.10/site-packages/mage_ai/orchestration/pipeline_scheduler_original.py\", line 319, in schedule\n    self.__schedule_blocks(block_runs)\n", "  File \"/usr/local/lib/python3.10/site-packages/mage_ai/orchestration/pipeline_scheduler_original.py\", line 581, in __schedule_blocks\n    job_manager.add_job(\n", "  File \"/usr/local/lib/python3.10/site-packages/mage_ai/orchestration/job_manager.py\", line 27, in add_job\n    self.queue.enqueue(job_id, target, *args, **kwargs)\n", "  File \"/usr/local/lib/python3.10/site-packages/mage_ai/orchestration/queue/process_queue.py\", line 107, in enqueue\n    self.start_worker_pool()\n", "  File \"/usr/local/lib/python3.10/site-packages/mage_ai/orchestration/queue/process_queue.py\", line 173, in start_worker_pool\n    self.worker_pool_proc.start()\n", "  File \"/usr/local/lib/python3.10/multiprocessing/process.py\", line 121, in start\n    self._popen = self._Popen(self)\n", "  File \"/usr/local/lib/python3.10/multiprocessing/context.py\", line 224, in _Popen\n    return _default_context.get_context().Process._Popen(process_obj)\n", "  File \"/usr/local/lib/python3.10/multiprocessing/context.py\", line 281, in _Popen\n    return Popen(process_obj)\n", "  File \"/usr/local/lib/python3.10/multiprocessing/popen_fork.py\", line 19, in __init__\n    self._launch(process_obj)\n", "  File \"/usr/local/lib/python3.10/multiprocessing/popen_fork.py\", line 71, in _launch\n    code = process_obj._bootstrap(parent_sentinel=child_r)\n", "  File \"/usr/local/lib/python3.10/multiprocessing/process.py\", line 314, in _bootstrap\n    self.run()\n", "  File \"/usr/local/lib/python3.10/multiprocessing/process.py\", line 108, in run\n    self._target(*self._args, **self._kwargs)\n", "  File \"/usr/local/lib/python3.10/site-packages/mage_ai/orchestration/queue/process_queue.py\", line 275, in poll_job_and_execute\n    worker.start()\n", "  File \"/usr/local/lib/python3.10/multiprocessing/process.py\", line 121, in start\n    self._popen = self._Popen(self)\n", "  File \"/usr/local/lib/python3.10/multiprocessing/context.py\", line 224, in _Popen\n    return _default_context.get_context().Process._Popen(process_obj)\n", "  File \"/usr/local/lib/python3.10/multiprocessing/context.py\", line 281, in _Popen\n    return Popen(process_obj)\n", "  File \"/usr/local/lib/python3.10/multiprocessing/popen_fork.py\", line 19, in __init__\n    self._launch(process_obj)\n", "  File \"/usr/local/lib/python3.10/multiprocessing/popen_fork.py\", line 71, in _launch\n    code = process_obj._bootstrap(parent_sentinel=child_r)\n", "  File \"/usr/local/lib/python3.10/multiprocessing/process.py\", line 314, in _bootstrap\n    self.run()\n", "  File \"/usr/local/lib/python3.10/site-packages/newrelic/api/background_task.py\", line 117, in wrapper\n    return wrapped(*args, **kwargs)\n", "  File \"/usr/local/lib/python3.10/site-packages/mage_ai/orchestration/queue/process_queue.py\", line 240, in run\n    start_session_and_run(args[1], *args[2], **args[3])\n", "  File \"/usr/local/lib/python3.10/site-packages/mage_ai/orchestration/db/process.py\", line 15, in start_session_and_run\n    results = target(*args)\n", "  File \"/usr/local/lib/python3.10/site-packages/mage_ai/orchestration/pipeline_scheduler_original.py\", line 1105, in run_block\n    return ExecutorFactory.get_block_executor(\n", "  File \"/usr/local/lib/python3.10/site-packages/mage_ai/data_preparation/executors/block_executor.py\", line 621, in execute\n    on_failure(\n", "  File \"/usr/local/lib/python3.10/site-packages/mage_ai/orchestration/db/__init__.py\", line 149, in func_with_rollback\n    return func(*args, **kwargs)\n", "  File \"/usr/local/lib/python3.10/site-packages/mage_ai/orchestration/pipeline_scheduler_original.py\", line 415, in on_block_failure\n    self.logger.exception(\n", "  File \"/usr/local/lib/python3.10/site-packages/mage_ai/data_preparation/logging/logger.py\", line 30, in exception\n    self.__send_message('exception', message, **kwargs)\n", "  File \"/usr/local/lib/python3.10/site-packages/mage_ai/data_preparation/logging/logger.py\", line 59, in __send_message\n    data['error_stack'] = traceback.format_stack(),\n"]], "error_stacktrace": ["'Open'"]}
Traceback (most recent call last):
  File "/usr/local/lib/python3.10/site-packages/pandas/core/indexes/base.py", line 3802, in get_loc
    return self._engine.get_loc(casted_key)
  File "pandas/_libs/index.pyx", line 138, in pandas._libs.index.IndexEngine.get_loc
  File "pandas/_libs/index.pyx", line 165, in pandas._libs.index.IndexEngine.get_loc
  File "pandas/_libs/hashtable_class_helper.pxi", line 5745, in pandas._libs.hashtable.PyObjectHashTable.get_item
  File "pandas/_libs/hashtable_class_helper.pxi", line 5753, in pandas._libs.hashtable.PyObjectHashTable.get_item
KeyError: 'Open'

The above exception was the direct cause of the following exception:

Traceback (most recent call last):
  File "/usr/local/lib/python3.10/site-packages/mage_ai/data_preparation/executors/block_executor.py", line 605, in execute
    result = __execute_with_retry()
  File "/usr/local/lib/python3.10/site-packages/mage_ai/shared/retry.py", line 54, in retry_func
    raise e
  File "/usr/local/lib/python3.10/site-packages/mage_ai/shared/retry.py", line 38, in retry_func
    return func(*args, **kwargs)
  File "/usr/local/lib/python3.10/site-packages/mage_ai/data_preparation/executors/block_executor.py", line 578, in __execute_with_retry
    return self._execute(
  File "/usr/local/lib/python3.10/site-packages/mage_ai/data_preparation/executors/block_executor.py", line 1052, in _execute
    result = self.block.execute_sync(
  File "/usr/local/lib/python3.10/site-packages/mage_ai/data_preparation/models/block/__init__.py", line 1285, in execute_sync
    raise err
  File "/usr/local/lib/python3.10/site-packages/mage_ai/data_preparation/models/block/__init__.py", line 1194, in execute_sync
    output = self.execute_block(
  File "/usr/local/lib/python3.10/site-packages/mage_ai/data_preparation/models/block/__init__.py", line 1509, in execute_block
    outputs = self._execute_block(
  File "/usr/local/lib/python3.10/site-packages/mage_ai/data_preparation/models/block/__init__.py", line 1665, in _execute_block
    outputs = self.execute_block_function(
  File "/usr/local/lib/python3.10/site-packages/mage_ai/data_preparation/models/block/__init__.py", line 1704, in execute_block_function
    output = block_function_updated(*input_vars, **global_vars)
  File "<string>", line 32, in load_data
  File "/home/src/./src/data_ingestion/download_ticker_data.py", line 64, in download_ticker_data
    response_dict[symbol] = vbt.AlpacaData.download_symbol(symbol, start=start_date, end=end_date)
  File "/usr/local/lib/python3.10/site-packages/vectorbt/data/custom.py", line 917, in download_symbol
    df['Open'] = df['Open'].astype(float)
  File "/usr/local/lib/python3.10/site-packages/pandas/core/frame.py", line 3807, in __getitem__
    indexer = self.columns.get_loc(key)
  File "/usr/local/lib/python3.10/site-packages/pandas/core/indexes/base.py", line 3804, in get_loc
    raise KeyError(key) from err
KeyError: 'Open'
2024-04-14T23:38:25 {"cpu": 1.12451171875, "cpu_total": 4, "cpu_usage": 0.2811279296875, "memory": 5367.0, "memory_total": 8874.0, "memory_usage": 0.6048005409060175, "pipeline_run_id": 124, "pipeline_schedule_id": 1, "pipeline_uuid": "fantastic_spellcaster", "hostname": "65ebb88fe12a", "level": "INFO", "message": "Pipeline fantastic_spellcaster for run 124 in schedule 1 is alive.", "timestamp": 1713137905.445497, "uuid": "a5be309030e844d48fa0bb89a65c2941"}
